Workbook

Sheet README
A1: Supplementary Data tables for Wong Hearing et al.: "Humans could become the greatest driver of biosphere net gain in Earth history, but are currently the second fastest driver of biosphere loss"
A3: Explanation of sheets
A4: references | B4: literature sources cited in the supplementary data tables
A5: table_s1_transient | B5: Table S1. Examples of transient disruptors in Earth's deep past is associated with substantial habitat loss caused, for example, by global changes in climate and low oxygen concentrations in the marine realm. Unless otherwise stated, data follow Bond and Grasby (2017), Foster et al (2018), and Kiessling et al (2025).
A6: table_s2_persistent | B6: Table S2. Examples of persistent disruptors in Earth's deep past is associated with substantial biosphere change, and humans both near-past to contemporary and possible future as persistent disruptors.
A7: table_s3_durations | B7: Table S3. Reference table for transient, persistent, and human disruptors used in our analyses including numerical age, duration, and background climate state for each disruption episode.
A8: table_s4_summaries | B8: Table S4. Summary statistics of the durations (Table S3) of transient and persistent disruptors. These values are quoted in the main text.
A9: table_s5_biosphere_changes | B9: Table S5. Quantitative changes (positive or negative) of biosphere metrics (taxonomic richness, productivity, biomass) used for our analyses. Values presented in figures 2 and S4.

Sheet references
A1: short_ref | B1: full_ref
A2: estimate | B2: our calculated estimate with details provided in notes
A3: Bambach 2006 | B3: Bambach RK. 2006 Phanerozoic Biodiversity Mass Extinctions. Annual Review of Earth and Planetary Sciences 34, 127–155. (doi:10.1146/annurev.earth.33.092203.122654)
A4: Barnosky & Hadly 2026 | B4: Barnosky A, Hadly E. 2026 The new Anthropocene biosphere. Philos Trans R Soc Lond B Biol Sci 381, 20240428. (doi:10.1098/rstb.2024.0428)
A5: Barnosky 2008 | B5: Barnosky AD. 2008 Megafauna biomass tradeoff as a driver of Quaternary and future extinctions. Proceedings of the National Academy of Sciences 105, 11543–11548. (doi:10.1073/pnas.0801918105)
A6: Bar-On et al 2018 | B6: Bar-On YM, Phillips R, Milo R. 2018 The biomass distribution on Earth. Proceedings of the National Academy of Sciences 115, 6506–6511. (doi:10.1073/pnas.1711842115)
A7: Battison & Brasier 2012 | B7: Battison L, Brasier MD. 2012 Remarkably preserved prokaryote and eukaryote microfossils within 1Ga-old lake phosphates of the Torridon Group, NW Scotland. Precambrian Research 196–197, 204–217. (doi:10.1016/j.precamres.2011.12.012)
A8: Benton et al 2022 | B8: Benton MJ, Wilf P, Sauquet H. 2022 The Angiosperm Terrestrial Revolution and the origins of modern biodiversity. New Phytologist 233, 2017–2035. (doi:10.1111/nph.17822)
A9: Betts et al 2018 | B9: Betts HC, Puttick MN, Clark JW, Williams TA, Donoghue PCJ, Pisani D. 2018 Integrated genomic and fossil evidence illuminates life’s early evolution and eukaryote origin. Nat Ecol Evol 2, 1556–1562. (doi:10.1038/s41559-018-0644-x)
A10: Blackburn et al 2013 | B10: Blackburn TJ, Olsen PE, Bowring SA, McLean NM, Kent DV, Puffer J, McHone G, Rasbury ET, Et-Touhami M. 2013 Zircon U-Pb Geochronology Links the End-Triassic Extinction with the Central Atlantic Magmatic Province. Science 340, 941–945. (doi:10.1126/science.1234204)
A11: Bond & Grasby 2017 | B11: Bond DPG, Grasby SE. 2017 On the causes of mass extinctions. Palaeogeography, Palaeoclimatology, Palaeoecology 478, 3–29. (doi:10.1016/j.palaeo.2016.11.005)
A12: Bond et al 2019 | B12: Bond DPG, Wignall PB, Grasby SE. 2019 The Capitanian (Guadalupian, Middle Permian) mass extinction in NW Pangea (Borup Fiord, Arctic Canada): A global crisis driven by volcanism and anoxia. GSA Bulletin 132, 931–942. (doi:10.1130/B35281.1)
... A114: Zhuravlev et al 2023 | B114: Zhuravlev AYu, Wood RA, Bowyer FT. 2023 Cambrian radiation speciation events driven by sea level and redoxcline changes on the Siberian Craton. Science Advances 9, eadh2558. (doi:10.1126/sciadv.adh2558)

Sheet table_s1_transient
A1: Biotic episode (turnover or extinction) | B1: Age (millions of years ago) [a] | C1: Duration | D1: Proximate cause of biotic event (if known) | E1: Background climate state [b] | F1: Mean global surface temperature change | G1: Ocean deoxygenation (hypoxic or anoxic conditions) | H1: Ocean acidification | I1: Carbon isotope shift (indicator of carbon cycle disruption) | J1: Biosphere impact
A2: Recent past and contemporary (Quaternary) | B2: 0.3 | C2: 1000s of years for the anthropogenic extinction episode; maximum impact in last ~200 years | D2: Human activity | E2: Coldhouse | F2: Warming | G2: Yes | H2: Yes | I2: Uncertain; currently at least –1‰ in the surface ocean and –2‰ in the atmosphere (Kwon et al. 2022) | J2: Potential mass extinction and significant decline in biomass; instability and loss of ecosystems and functional diversity; human appropriation of primary productivity and concentration of animal and plant biomass in a few species deemed useful for human (70% of bird biomass in chickens; 98% of mammal biomass in humans and farmed animals)
A3: Eocene-Oligocene transition (Palaeogene) [c] | B3: 34 | C3: <1 Myr in total (Hutchinson et al. 2021) with shorter-duration marine extinction events of 5 kyr (Pearson et al. 2008) | D3: Climate cooling and reorganisation of ocean circulation with the initiation Antarctic ice sheets | E3: Warmhouse | F3: Cooling (-1 to -5°C; Hutchinson et al. 2021) | G3: No | H3: No | I3: +1.25‰ (following Westerhold et al. 2020) | J3: ‘Grande Coupure’ of mammals, loss of marine plankton and benthos (see Hutchinson et al 2021)
A4: Palaeocene-Eocene Thermal Maximum (Palaeogene) | B4: 56 | C4: ~170 kyr | D4: Hyperthermal | E4: Hothouse | F4: Warming (+8°C) | G4: Limited? | H4: Yes | I4: –3 to –5‰ (McInerney and Wing 2011) | J4: 1 to 20% loss of species
A5: Cretaceous-Palaeogene boundary | B5: 66 | C5: Seconds to millennia for K-Pg boundary extinction; maximum impact duration <20 to 30 years following modelling work (Brugger et al 2017; Chiarenza et al 2020; Morgan et al 2022), but note the wide temporal range of impact on the biosphere during this event | D5: Bolide impact (impact winter) on the background of prolonged Deccan Traps volcanism | E5: Greenhouse | F5: Variable (intense fires and month to decadal-scale cooling; Vellekoop et al 2014; Gulick et al 2019) | G5: After extinction | H5: Yes | I5: –2‰ | J5: Mass extinction, significant loss of biomass
A6: OAE-2 (Cenomanian-Turonian; Cretaceous) | B6: 94 | C6: ~500 kyr (Gale et al. 2020, but estimates vary) | D6: Uncertain; possibly the Caribbean–Colombian LIP (Gale et al. 2020) | E6: Hothouse | F6: Warming | G6: Yes | H6: Yes | I6: +2.5‰ (Gale et al. 2020) | J6: 20% loss of species
A7: OAE-1a (Aptian; Cretaceous) | B7: ~120 | C7: 1.116 Myr (Gale et al 2020; Li et al 2024) | D7: LIP eruptions; possibly the Ontong Java Plateau LIP (Li et al 2024) but note potential age discrepancy; possibly also the emplacement of the Barents Sea Sill Complex (Jenkyns 2018; Gale et al. 2020) | E7: Hothouse | F7: Warming | G7: Yes | H7: Yes | I7: Short-lived (<50 kyr) –1 to –1.5‰ excursion followed by longer duration +2‰ excursion (Jenkyns 2018; Gale et al. 2020) | J7: 22% loss of species
A8: T-OAE (Toarcian; Jurassic) | B8: ~183 | C8: Likely >1 Myr but possibly as short as ~200 kyr (Hesselbo et al 2020) | D8: Karoo-Ferrar LIP eruption possibly with methane hydrate release (Hesslebo et al. 2020) | E8: Warmhouse | F8: Warming | G8: Yes | H8: Yes | I8: –4 to –7‰ (Hesselbo et al. 2020) | J8: 15 to 20% loss of species
A9: End-Triassic | B9: 201 | C9: ~1.2 Myr (Schoepfer et al 2022) | D9: Eruption of the Central Atlantic Magmatic Province (CAMP) LIP | E9: Coolhouse | F9: Warming (+6°C) | G9: Yes | H9: Yes | I9: –1.5‰ (Foster et al. 2018) | J9: Mass extinction: 80% loss of species; significant decline in biomass
A10: Carnian (Triassic) | B10: ~234 | C10: ~1.7 Myr (though possibly as short as 1.2 Myr; Dal Corso et al 2020) | D10: Wrangellia LIP | E10: Transitional (warming trend) | F10: Warming (+7°C) | G10: Yes | H10: Uncertain | I10: Several negative excursions of up to –5‰ (Dal Corso et al. 2020) | J10: ~35% loss of marine genera, as well as major radiations including of dinoflagellates (Dal Corso et al. 2020)
A11: Smithian-Spathian Boundary (Olenekian; Triassic) [d] | B11: 248 | C11: <1 Myr (Ogg et al 2020) | D11: Late-stage Siberian Traps | E11: Warmhouse | F11: Warming (+6°C) | G11: Yes | H11: Uncertain | I11: –6 ‰ then +6‰ | J11: Reset of marine biodiversity to earliest Triassic levels (Ogg et al 2020)
A12: Permo-Triassic Mass Extinction | B12: 252 | C12: ~60 ± 48 kyr (Burgess et al 2014) to 31 ± 31 kyr (Shen et al 2018) | D12: Siberian Traps | E12: Greenhouse | F12: Warming (+10°C) | G12: Yes | H12: Probably | I12: –8‰ | J12: Mass extinction; 90 to 95% loss of species; significant decline in biomass
A13: Capitanian biodiversity crisis (end-Guadalupian; Permian) | B13: ~262 | C13: Uncertain; <2 Myr (within the Jinogondolella altudaensis and J. prexuanhanensis biozones; Bond et al 2019) | D13: Emeishan Traps LIP; volcanic winter and photosynthesis shutdown plus heavy metal poisoning | E13: Coolhouse | F13: Both warming and cooling have been invoked | G13: Regionally | H13: Possibly | I13: –6‰ | J13: 25 to 47% marine genus extinction, especially of reef ecosystems
A14: Serpukhovian (late Mississippian; Carboniferous) | B14: 325 | C14: poorly constrained | D14: Possibly interglacial warming plus associated marine anoxia (Chen et al 2025) and prolonged unstable ocean redox conditions (Hu et al 2022) around the onset or early intensification of LPIA glaciation (Montanez & Poulsen 2013) | E14: Coldhouse | F14: Warming (+5°C in tropics) | G14: Yes | H14: Uncertain | I14: Negative excursion | J14: Possible mass extinction; significant ecological crisis of uncertain magnitude; up to 39% genus-level extinction (McGhee et al 2013) and low levels of speciation
A15: Hangenberg Event (end-Famennian; Devonian) | B15: 360 | C15: <1 Myr; two phases with marine extinction followed by terrestrial extinction pulse (McGhee et al 2013) | D15: Pripyat-Dnieper-Donets rift system volcanism or intense glaciation | E15: Transitional (background cooling) | F15: Warming and cooling? | G15: Yes | H15: Uncertain | I15: +6‰ | J15: Poorly understood; estimates range between ~7 to 50% marine genus extinction (see Bond & Grasby 2017)
A16: Upper and Lower Kellwasser events (Frasnian – Famennian; Late Devonian) | B16: 371 | C16: ~600 kyr between the Lower and Upper Kellwasser events (De Vleeschouwer et al 2017) with each event lasting ~90 and 110 kyrs (Da Silva et al 2020) | D16: Pripyat-Dnieper-Donets rift system volcanism? Viluy Traps? Siljan Ring? Climatic instability? | E16: Warmhouse | F16: Cooling pulses of ~3 and ~6°C in low latitude shallow seas (Huang et al. 2018) | G16: Yes | H16: Uncertain | I16: +4‰ | J16: One of the ‘Big 5’ with a particularly pronounced loss of reef ecosystems
A17: Taghanic Event (Giventian; Middle Devonian) | B17: 381 | C17: Uncertain; perhaps ~1 to 2 Myr; diachronous main extinction pulse | D17: Uncertain; climatic instability? | E17: Warmhouse | F17: Possibly extreme warming (“overheating”) at the start of a protracted warming trend (Becker et al. 2020) | G17: Yes | H17: Uncertain | I17: +2‰ | J17: Pelagic extinctions (including goniatites) preceded benthic extinctions (including reef ecosystem taxa)
A18: Kačák Event (Eifelian; Middle Devonian) | B18: 386 | C18: ~370 kyr with main anoxic pulse ~100 kyr (Kabanov et al. 2023) | D18: Uncertain; climatic instability? | E18: Transitional (becoming warmhouse?) | F18: Warming | G18: Yes | H18: Possibly (loss of benthic carbonate production; Kabanov et al. 2023) | I18: Several ±1 to 1.5‰ CIEs (Kabanov et al. 2023) | J18: Multiphase event with between 6 to 32% genus extinction
A19: Lau Event (Ludfordian; Ludlow; Silurian) | B19: 423.5 | C19: Uncertain; possibly ~1 Myr (following Melchin et al. 2020) | D19: Uncertain; possible ecosystem collapse | E19: Hothouse | F19: Cooling | G19: Yes | H19: Uncertain | I19: +6‰ | J19: Extinction of conodonts and graptolites; possible major loss of primary productivity; 20 to 25% marine genus extinction?
A20: Mulde Event (Homerian; Wenlock; Silurian) | B20: 428 | C20: Uncertain; possibly 2 Myr in total; the first excursion may be very short | D20: Uncertain; possible ecosystem collapse | E20: Coolhouse | F20: Cooling | G20: Yes | H20: Uncertain | I20: +4‰ (double-spike excursion of +4‰ followed by a partial recovery to ~2‰ and additional +1 ‰ spike before full recovery) | J20: Extinction of conodonts and graptolites; possible major loss of primary productivity; 20 to 25% marine genus extinction?
A21: Ireviken Event (Sheinwoodian; Wenlock; Silurian) | B21: 433 | C21: Uncertain; possibly ~1 to 1.5 Myr with a protracted recovery phase? | D21: Uncertain; possible ecosystem collapse | E21: Coolhouse | F21: Cooling | G21: Yes | H21: Uncertain | I21: +3‰ then –5‰ | J21: Extinction of conodonts and graptolites; possible major loss of primary productivity; 20 to 25% marine genus extinction?
A22: Late Ordovician Extinction Event (Hirnantian; Late Ordovician) | B22: 445 | C22: Pulsed event over ~1.4 Myr with two extinction pulses on 10 to 100 kyr timescales (Harper 2024); the major extinction pulses were probably ~340 +460/-340 kyr and ~60 +310/-60 kyr (Zhang et al 2025); there is a possible precursor extinction in the early Katian lasting ~1-2 Myr (Deng et al 2021) | D22: Cooling, lower sea level and loss of marine shelf LOME1; followed by warming and ocean anoxia LOME2 | E22: Icehouse | F22: Cooling followed by warming? | G22: Possibly | H22: Uncertain | I22: +7‰ then –7‰ | J22: One of the ‘Big 5’; ~43 to 73% marine genus extinction
A23: Steptoean Positive Carbon Isotope Excursion (SPICE) / End-Marjuman Biomere Extinction (EMBE; Paibian, Cambrian) | B23: 495 | C23: ~2.6 Myr (Farrell et al. 2025) | D23: Uncertain | E23: Hothouse or warmhouse | F23: Possible cooling | G23: Yes | H23: Uncertain | I23: +5‰ | J23: Trilobite biotope extinctions
A24: Redlichiid-Olenellid trilobite Extinction Carbon isotope Excursion (ROECE; Cambrian Stage 4–Miaolingian boundary) [e] | B24: ~507 (following revised age of 506.5 Ma for the base of the Miaolingian) | C24: Uncertain; possibly <1 Myr | D24: Uncertain; possibly Kalkarindji LIP | E24: Hothouse | F24: Possible warming | G24: Probably | H24: Uncertain | I24: –4 to –5‰ | J24: Global trilobite extinction
A25: Sinsk Event / Archaeocyath Extinction Carbon isotope Excursion (AECE; Cambrian Stage 4) [e] | B25: ~513 | C25: Uncertain | D25: Uncertain | E25: Hothouse | F25: Possible warming | G25: Yes | H25: Uncertain | I25: –4‰ | J25: Major extinctions of archaeocyathan reefs and hyoliths and possibly of metazoan phylum stem groups
A26: [a] For information on timescales and stratigraphical nomenclature used here see Gradstein et al. (2020).
A27: [b] Background climate state follows Judd et al. (2024) except for Cambrian events which are considered hothouse (early) and hothouse or warmhouse (late).
A28: [c] The EOT is included in Kiessling et al. (2025) with no warming, no deoxygenation, and no ocean acidification. The biotic event is assigned with “medium” confidence to a climate change cause, which was “likely cooling”.
A29: [d] It has not been possible to determine a biosphere impact for the Smithian-Spathian boundary episode, so it does not feature in the biosphere impact analyses.
A30: [e] Two biotic events near the Cambrian Stage 4–Miaolingian boundary are identified here, both of which are linked to negative carbon isotope excursions and expanded marine anoxia. These events are not well understood, but they were critical in shaping the early evolution of animals and anoxia was likely a major driver of the extinctions (see for example Zhuravlev and Wood 1996, 2018).

Sheet table_s2_persistent
A1: Biotic episode/event | B1: Onset age | C1: Geological interval | D1: Duration | E1: Key Earth System changes | F1: Key impacts on the incumbent biosphere | G1: Long term impact (for e.g. on complexity, functional and taxonomic biodiversity, biomass) | H1: Fossil record
A2: Humans with sustainable stewardship | B2: 0.3 Ma for initial onset; nascent for millennia; re-emerging | C2: Pleistocene through Anthropocene | D2: Contemporary | E2: Path-dependent Some warming on a background coolhouse (assuming some baked-in heating and loss of ice sheets) state followed by limited cooling and climate stabilisation Temporary ocean deoxygenation and acidification locally | F2: Negative: already established biosphere destabilisation and degradation creates a genetic bottleneck effect and irreversible loss of some species and habitats; global biosphere reconfiugration from translocation of non-native species leads to some extinction of incumbent species Positive: biodiversity decline is ultimately reversed; most incumbent ecosystems are supported back to stability; novel ecologies are fostered with reconfigured complements of species | G2: Positive: increased productivity, enhanced biodiversity in novel and human maintained ecosystems (land sparing and land sharing); maintenance and extension of marine protected areas supports long-term stability or seascapes; enhanced mutualism and symbioses as well as hybridisation and speciation supports a more diverse global biosphere | H2: Developing
A3: Angiosperm Terrestrial Revolution | B3: 140 Ma for initial diversification ~100 Ma for start of major radiation (Benton et al 2022) | C3: Cretaceous to Palaeogene | D3: 50 to 100 Myr | E3: Enhanced habitability of tropical wet biomes | F3: Negative: competitive replacement of gymnosperm plants | G3: Positive: more than 80% of standing biomass concentrated on land (most is in angiosperms). Improved photosynthetic efficiency of plants. Enhanced range of symbiotic relationships between plants, fungi, microbes and animals. Terrestrial environments become home to 85 to 95% of all macrospecies diversity | H3: Yes
A4: Mesozoic Marine Revolution | B4: Uncertain; possibly diffuse start ~240 Ma (initial dominance of calcareous over other foraminferal test compositions; Faulkner et al 2025) ~200 Ma (initial rise of coccolithophores; Brown et al 2004, Monteiro et al 2016) ~170 Ma (mid-Jurassic change from abiotic to biotic control of marine carbonate ecology; Eichenseer et al 2019) ~150 Ma (major inflection in number of foraminiferal genera with calcareous tests and increase in number of planktic foraminiferal genera; Faulkner et al 2025) | C4: mid-Mesozoic (~Late Triassic through Cretaceous) | D4: Uncertain duration due to uncertain onset age Calcareous plankton taxonomically and ecologically established by mid-Cretaceous (~100 Ma; e.g. Zeebe & Westbroek 2003, Brown et al 2004, Monteiro et al 2016, Eichenseer et al 2019, Faulkner et al 2025) Duration estimate from ~50 to 100 Myr (200 or 150 Ma to 100 Ma) | E4: Evolution and diversification of phytoplankton including mixotrophic dinoflagellates, calcifying nanoplankton, and planktic foraminifera (Knoll & Follows 2016) Diversification and increasing abundance of calcifying plankton (notably foraminifera and coccolithophores) changed the ocean carbon cycle and stabilised the ocean carbonate cycle, changed (deepened) the locus of marine carbonate deposition from neritic/platform carbonates to deep ocean settings, and buffered ocean chemistry against extreme perturbations of alkalinity and pH (Zeebe & Westbroek 2003, Ridgwell 2005) Ocean chemical cycles and marine calcification control changed from abiotic to biotic (Eichenseer et al 2019) | F4: Positive: increased primary productivity provides greater nutrient flows to higher trophic tiers; new ecological niches from the expansion and diversification of marine phytoplankton | G4: Positive: increase in marine primary productivity with more energy flowing to higher trophic tiers (Knoll & Follows 2016); increased ecosystem resilience through stabilisation of marine carbon, carbonate, and pH cycles and damped perturbations (Ridgwell 2005); enhanced energy flow (productivity) from pelagic to benthic realms with onset of marine ecosystem benthic-planktic coupling (Kotake 2014, Izumi 2015, Buatois et al 2016, Knoll & Follows 2016); increase in propotion of skeletal biomass from protists (Singh et al 2025); quadrupling of foraminiferal genus diversity (Faulkner et al 2025) | H4: Yes, but very challenging to quantify
A5: Terrestrialization of plants | B5: ~475 Ma for initial colonisation (or possibly earlier: late Cambrian) Major radiation of vascular plants from ~430 Ma (late Silurian; Morris et al 2018; Donoghue et al 2021) Established plant biosphere with forests by ~360 Ma (Capel et al 2023) | C5: Ordovician through Devonian | D5: 30 to 100 Ma (main revolution began in the late Silurian ~430 Ma Initial peak of genus and species diversity in the Early Devonian ~400 Ma (Morris et al 2018; Donoghue et al 2021) Terrestrial plant biosphere largely established by the Late Devonian ~360 Ma (Capel et al 2023) | E5: Changes to hydrology and landforms (meandering rivers), changed terrestrial weathering patterns Changes to Earth's atmosphere (increased oxygen, especially in the Carboniferous Period) | F5: Positive: extension of planetary habitability onto land, forging and extension of symbioses between plants and fungi | G5: Positive: enhanced overall biomass, with most concentrated on land; fostered complex interactions between plants, animals, fungi and microbes that enabled greater planetary habitability | H5: Yes
A6: Great Ordovician Biodiversification Event | B6: ~490 Ma (onset in the late Cambrian) to ~480 Ma (main increase in diversity from Early Ordovician) After the SPICE interval (Servais et al 2016) | C6: late Cambrian to Middle Ordovician | D6: ~30 Myr (latest Cambrian ~490 Ma to end of Middle Ordovician ~460 Ma) | E6: Global cooling from the warm (super)greenhouse conditions of the Cambrian and Early Ordovician (e.g. Trotter et al 2008) Diversification of marine phytoplankton from the late Cambrian (Servais et al 2016, Kroeck et al 2022) Diversification of zooplankton and nekton from the Early Ordovician including graptolites and cephalopods (Servais et al 2016, Harper et al 2020) | F6: Negative: competitive replacement of the incumbent "Cambrian evolutionary fauna" with a more diverse range of taxa comprising the "Palaeozoic evolutionary fauna" (Sepkoski 1981, Rojas et al 2021) | G6: Positive: diversifying plankton provided increase productivity and fuelled the diversification of phyla which had evolved in the preceding Cambrian Period; approximately 9-fold increase in marine metazoan genus diversity (Harper et al 2020) | H6: Yes
A7: Cambrian Agronomic Revolution | B7: ~545 Ma (onset of bioturbation revolution between ~550 to 540 Ma and persisting through to Cambrian Epoch 2; Mángano et al 2024) | C7: Ediacaran to Cambrian | D7: 40 Myr (from ~545 to 507 Ma) | E7: Refashioned seabeds through the Cambrian agronomic revolution, refashioned biogeochemical cycles on the land and in the sea, for example the development of the fecal stream (marine snow) in the oceans, and changes to the marine sulfur cycle (see impacts on incumbent biosphere) as a result of marine burrowing organisms | F7: Negative: demise of marine microbial mat communities and associated mat 'miners' that characterised the Ediacaran, reduced ecospace for sulfate reducing organisms in marine sediments | G7: Positive: instrumental in developing complex marine and terrestrial foodwebs from primary consumers (like ostracods) to tertiary/apex predators (like sharks), thereby facilitating greater taxonomic and functional diversity. Essential for recycling biomass. | H7: Yes
A8: Neoproterozoic Oxygenation Event | B8: Uncertain; possibly ~580 to 540 Ma (Stockey et al 2024) or ~635 to ~540 Ma (Sperling et al 2022) or a broader distributed series of episodes from ~800 to 520 Ma (Lyons et al 2021; Shi et al 2026) | C8: Ediacaran (Neoproterozoic) | D8: Uncertain Possibly 20 to 40 Myr for main uplift in atmospheric oxygen Episodic uplifts and decreases in atmospheric oxygen over ~250 Myr (Shi et al 2026) | E8: Increase in atmospheric and shallow marine oxygenation without concomitant increase in deep ocean oxygen concentration (Stockey et al 2024) possibly driven by diversification of algal lineages (Brocks et al 2017; 2023) Possibly supported by increasing influence of cold subduction (Shi et al 2026) | F8: Negative: replacement/displacement/repression of encumbant cyanobacterial and low-oxygen adapted prokaryotes | G8: Positive: facilitated evolution of high energy-demand ecologies including motile and predatory metazoans (note this is a permissive threshold rather than a sufficient driver); possible two-fold increase in primary productivity (Stockey et al 2024); possibly ~250% increase in eukaryote species richness and ~100% increase in eukaryote genus richness (Tang et al 2024) but note uncertainty around timing | H8: Poor (predominantly biomarkers; eukaryote fossil evidence reviewed in Tang et al 2024; note uncertainty in correlation)
A9: Eukaryogenesis (Symbiogenesis) | B9: 2300 to 1800 Ma (2220 Ma following Mills et al 2022) LECA <1840 Ma (Betts et al 2018) | C9: Palaeoproterozoic | D9: Uncertain 10s to 100s Myr | E9: Enabled a much more complex biosphere as the building blocks of most multicellular organsisms, and over time thereby extended plantetary habitability (e.g. terrestrialization) Changed numerous geochemical cycles (phosphorous, nitrogen, carbon, silica) Facilitated the construction of large structures from reefs to forests | F9: Positive: provided a greater range of habitats for bacterial and archaen symbionts to co-exist with; increased ecological adaptability | G9: Positive: facilitated the evolution of a multitude of morphologies from tiny unicells to giant trees. Provided a much greater range of habitats/niches for organisms to co-habit, for example bacteria in mammal guts or dinoflagellates in coral reefs. Through the evolution of plants, greatly increased the biomass on Earth and extended habitability onto land | H9: Yes (but unquantifiable)
A10: Oxygenic photosynthesis | B10: 2400 Ma (perhaps earlier) | C10: Archean-Proterozoic boundary | D10: 200 to 300 Myr | E10: Great Oxidation (Oxygenation) Episode (Event) [GOE] Oxygenation of the atmosphere and hydrosphere, oxidation of surface rocks and minerals (geosphere) Impact on global climate and cryosphere (cooling and snowball glaciation) Possibly supported by early influence of cold subduction (Shi et al 2026) | F10: Negative: lethal to anaerobic ecologies, likely large scale extinction and short term biomass loss | G10: Positive: enabled the surface biosphere to become largely independent of chemical sources of energy, and thus global in extent, utilising light, CO2 and water as the basis for building biomass. Increased biomass, ultimately leading to most (80% +) being locked in the tissues of land plants. Facilitated development of oxidative phosphorylation, providing much more energy to living cells than anaerobic respiration | H10: No (evidence of oxygenation from the geochemical record)
A11: RuBisCO enzyme | B11: 3800 Ma | C11: early Archean | D11: Uncertain 10s to 100s Myr (evolution of RuBisCo forms I to IV) | E11: Ultimately enabled the development of an oxygenated atmosphere and hydrosphere Enabled the biosphere to become global (and independent of primary chemical sources of energy) Underpins the acquisition of the primary source of chemical energy for life | F11: Positive: enabled fixation of CO2 as organic carbon and thus increased productivity and ultimately biomass | G11: Positive: RuBisCO is essential for photosynthesis and is the most abundant enzyme in the world; fundamental to underpining marine and terrestrial foodwebs | H11: No
A12: Horizontal gene transfer | B12: 4100 to 3700 Ma | C12: Latest Hadean to early Archean | D12: Uncertain (but probably close to inception of life) | E12: May have been instrumental in enabling life to cross the Gaian bottleneck, facilitating innovations that regulated a habitable environment over long timeframes, i.e. maintaining liquid water at Earth's surface over billions of years Also fundamental for maintaining plate tectonics and a dynamic rock cycle | F12: Positive: increased adaptation, emergence of new traits, ability to colonise new niches, enhanced functional diversity Negative: increased functional diversity may have impacted taxonomic diversity via competitive replacement | G12: Positive: for e.g., likely enabled transfer of key traits, for example RuBisCO genes essential for photosynthesis (see above) | H12: No

Sheet table_s3_events
A1: interval_name | B1: interval_abbreviation | C1: big5 | D1: big3_hatfield | E1: type | F1: background_climate | G1: age_estimate_ma | H1: event_duration_min_yr | I1: event_duration_max_yr | J1: event_duration_est_yr | K1: event_duration_notes
A2: 3100 persistent - sustainable stewardship | B2: sustainable stewardship: 3100 | E2: sustainable stewardship | F2: Icehouse | G2: -0.0011 | H2: 70 | I2: 53000 | J2: 3300 | K2: minimum duration of human impacts on decadal scale; minimum duration 150 years by definition; maximum duration up to 50 kyr human impact; extended to 3100 CE
A3: 3100 transient - business as usual | B3: business as usual: 3100 | E3: business as usual | F3: Icehouse | G3: -0.0011 | H3: 70 | I3: 53000 | J3: 3300 | K3: minimum duration of human impacts on decadal scale; minimum duration 150 years by definition; maximum duration up to 50 kyr human impact; extended to 3100 CE
A4: 2100 persistent - sustainable stewardship | B4: sustainable stewardship: 2100 | E4: sustainable stewardship | F4: Icehouse | G4: -0.0001 | H4: 70 | I4: 50000 | J4: 300 | K4: minimum duration of human impacts on decadal scale; minimum duration 150 years by definition; maximum duration up to 50 kyr human impact; most impact likely in 300 years before 2100
A5: 2100 transient - business as usual | B5: business as usual: 2100 | E5: business as usual | F5: Icehouse | G5: -0.0001 | H5: 70 | I5: 50000 | J5: 300 | K5: minimum duration of human impacts on decadal scale; minimum duration 150 years by definition; maximum duration up to 50 kyr human impact; most impact likely in 300 years before 2100
A6: Recent past | B6: humans so far | E6: humans so far | F6: Icehouse | G6: 0 | H6: 70 | I6: 50000 | J6: 200 | K6: minimum duration of human impacts on decadal scale; minimum duration 70 years assuming a 1950s Anthropocene base; maximum duration up to 50 kyr human impact (e.g. Barnosky 2008); most impact likely in last 200 years
A7: Pliocene-Pleistocene transition | B7: PP | E7: transient | F7: Icehouse | G7: 2.6 | H7: 100000 | I7: 1000000 | J7: 500000 | K7: main step-up in extinction rates between 3.6 to 2.9 Ma with a peak at ~2.6 Ma (Pimiento et al 2020)
A8: Eocene-Oligocene transition | B8: EOT | E8: transient | F8: Warmhouse | G8: 34 | H8: 5000 | I8: 1000000 | J8: 100000 | K8: <1 Myr in total (Hutchinson et al 2021) with shorter-duration marine extinction events of 5 kyr (Pearson et al 2008)
A9: Palaeocene-Eocene Thermal Maximum | B9: PETM | E9: transient | F9: Hothouse | G9: 56 | H9: 95000 | I9: 290000 | J9: 150000 | K9: total duration ~270 ± 20 kyr of which 145 to 195 kyr comprises CIE recovery following Piedrahita et al 2025
A10: Cretaceous-Palaeogene boundary | B10: K-Pg | C10: yes | D10: yes | E10: transient | F10: Greenhouse | G10: 66 | H10: 1e-07 | I10: 185000 | J10: 30 | K10: minimum duration of seconds following the bolide impact; maximum duration of hundreds of kiloyears for mammal recovery or one to tens of kiloyears for fern recovery (Clyde et al 2016); rapid recovery at the impact site (Lowery et al 2018) suggests that the extinction mechanism operated on timescales less than ocean mixing time (~1 kyr) with an estimated duration of decades to centuries (Chiarenza et al 2020); estimated duration of extinction mechanism on timescale of decades (Robertson et al 2013; Brugger et al 2017; Chiarenza et al 2020; Morgan et al 2022); duration <20 to 30 years following modelling work (Brugger et al 2017; Chiarenza et al 2020; Morgan et al 2022)
A11: OAE2 (Cenomanian-Turonian) | B11: OAE2 | E11: transient | F11: Hothouse | G11: 94 | H11: 30000 | I11: 930000 | J11: 500000 | K11: GTS 2020 estimate of ~500 kyr (Gale et al 2020); astrochronological estimates suggest >930 kyr for the whole event and ~30 kyr for the onset (Gangl et al 2019)
A12: OAE1a (Aptian) | B12: OAE1a | E12: transient | F12: Hothouse | G12: 120 | H12: 115000 | I12: 1116000 | J12: 500000 | K12: GTS 2020 estimate of ~1.1 Myr (Gale et al 2020); radiometric constraints agree giving 1.116 +0.087/-0.093 Myr with an onset duration of ~0.115 Myr (Li et al 2024)
A13: Angiosperm Terrestrial Revolution | B13: ATR | E13: persistent | F13: Warmhouse to hothouse | G13: 140 | H13: 50000000 | I13: 100000000 | J13: 75000000 | K13: crown angiosperms from ~140 Ma; main increase in diversity from ~100 Ma; Late Cretaceous to early Cenozoic; duration of ~50 to 100 Myr (Benton et al 2022)
A14: Jurassic-Cretaceous extinction (Tithonian) | B14: Tith | E14: transient | F14: Warmhouse | G14: 143.1 | H14: 100000 | I14: 5000000 | J14: 1000000 | K14: highly uncertain magnitude and duration; less than 5 Myr
A15: T-OAE (Toarcian) | B15: TOAE | E15: transient | F15: Warmhouse | G15: 183 | H15: 40000 | I15: 1000000 | J15: 500000 | K15: GTS 2020 estimate of 200 kyr to >1 Myr duration (Hesselbo et al 2020); Boulila et al 2019 support a duration of ~400 to 500 kyr including an onset within one obliquity cycle (~40 kyr)
A16: End-Triassic | B16: ETME | C16: yes | E16: transient | F16: Coolhouse | G16: 201 | H16: 40000 | I16: 1100000 | J16: 85000 | K16: zircon dates suggest an ~100 kyr duration for the event (Blackburn et al 2013); astrochronological calibration suggests ETME could have been as short as 20 to 40 kyr duration with a 120 kyr pre-recovery phase (Ruhl et al 2010) though a more recent study found a longer duration of 85 ± 25 kyr for the main event and a total excursion duration of 1.09 ± 0.07 Myr (Yager et al 2017)
A17: Carnian (Triassic) | B17: Carn | E17: transient | F17: Transitional (warming trend) | G17: 234 | H17: 800000 | I17: 1200000 | J17: 1090000 | K17: astrochronology calibrates five short-lived CIEs to a total duration of 1.09 Myr (Miller et al 2017); other astrochronology agrees that the interval spans two to three 405 kyr cycles with a total duration of 0.8 to 1.2 Myr (Zhang et al 2015)
A18: Smithian/Spathian (Triassic) | B18: Sm-Sp | E18: transient | F18: Warmhouse | G18: 248 | H18: 100000 | I18: 1800000 | J18: 1000000 | K18: poorly constrained; GTS 2020 estimates <1 Myr duration (Ogg et al 2020); biozones in Goudemand et al 2019 suggest up to 1.8 Myr is plausible
A19: Permo-Triassic mass extinction | B19: PTME | C19: yes | D19: yes | E19: transient | F19: Greenhouse | G19: 252 | H19: 10000 | I19: 1000000 | J19: 60000 | K19: carbon cycle destabilisation and marine extinction occurred over ~60 ± 48 kyr (Burgess et al 2014; Hua et al 2023) though it may have been as short as ~31 ± 31 kyr (Shen et al 2018); terrestrial extinction phase may have lasted as long as ~1 Myr (Hua et al 2023)
A20: End-Guadalupian (Capitanian; Permian) | B20: Capt | E20: transient | F20: Coolhouse | G20: 262 | H20: 500000 | I20: 4000000 | J20: 1500000 | K20: uncertain; likely a mid-Capitanian event <4 Myr duration and within the Jinogondolella altudaensis and Jinogondolella prexuanhanensis biozones possibly 1.5 Myr (Bond et al 2019)
A21: Serpukhovian (late Mississippian; Carboniferous) | B21: Serp | E21: transient | F21: Icehouse | G21: 325 | H21: 1000000 | I21: 7000000 | J21: 4000000 | K21: redox instability and biotic crises span the Serpukhovian Stage which is ~7 Myr duration (e.g. Hu et al 2022)
A22: Hangenberg Event (end-Devonian) | B22: Hang | E22: transient | F22: Transitional (background cooling) | G22: 360 | H22: 50000 | I22: 300000 | J22: 100000 | K22: radiometric constraints suggest ~50 to 100 kyr for deposition of the Hangenberg Shale (Myrow et al 2014) with the whole interval perhaps up to 300 kyr
A23: Frasnian-Famenian (Late Devonian) | B23: Fr-Fm | C23: yes | E23: transient | F23: Warmhouse | G23: 371 | H23: 90000 | I23: 600000 | J23: 100000 | K23: ~600 kyr between the Lower and Upper Kellwasser events (De Vleeschouwer et al 2017) with each event lasting ~90 and 110 kyrs (Da Silva et al 2020)
A24: Taghanic Event (Giventian, Middle Devonian) | B24: Tagh | E24: transient | F24: Warmhouse | G24: 381 | H24: 100000 | I24: 2000000 | J24: 1500000 | K24: uncertain; perhaps ~1 to 2 Myr; diachronous main extinction pulse
A25: Kačák Event (Eifelian, Middle Devonian) | B25: Kacak | E25: transient | F25: Transitional (becoming warmhouse?) | G25: 386 | H25: 10000 | I25: 370000 | J25: 100000 | K25: ~370 kyr with main anoxic pulse ~100 kyr (Kabanov et al 2023)
A26: Lau Event (Ludfordian, Ludlow, Silurian) | B26: Lau | E26: transient | F26: Hothouse | G26: 423.5 | H26: 100000 | I26: 1000000 | J26: 500000 | K26: uncertain; possibly ~1 Myr following Melchin et al 2020
A27: Mulde Event (Homerian, Wenlock, Silurian) | B27: Mulde | E27: transient | F27: Coolhouse | G27: 428 | H27: 100000 | I27: 2000000 | J27: 1000000 | K27: uncertain; possibly 2 Myr in total; the first excursion may be very short
A28: Ireviken Event (Sheinwoodian, Wenlock, Silurian) | B28: Irev | E28: transient | F28: Coolhouse | G28: 433 | H28: 100000 | I28: 1500000 | J28: 1000000 | K28: uncertain; possibly ~1 to 1.5 Myr with a protracted recovery phase?
A29: Late Ordovician Mass Extinction | B29: LOME | C29: yes | D29: yes | E29: transient | F29: Icehouse | G29: 445 | H29: 60000 | I29: 1400000 | J29: 500000 | K29: mass extinction interval likely <1.4 Myr duration with two pulses of extinction on 10 to 100 kyr timescales (Harper 2024); pulses possibly 340 +460/-340 kyr and 60 +310/-60 kyr following radiometric dates (Zhang et al 2025); possible precursor extinction in the early Katian lasting ~1-2 Myr (Deng et al 2021)
A30: Land plant evolution | B30: land plants | E30: persistent | F30: various | G30: 475 | H30: 30000000 | I30: 90000000 | J30: 60000000 | K30: initial colonisation in late Cambrian or Early Ordovician (Morris et al 2018; Donoghue et al 2021); main revolution began in the late Silurian ~430 Ma with an initial peak of genus and species diversity in the Early Devonian ~400 Ma and a largely established terrestrial plant biosphere by the Late Devonian ~360 Ma (Capel et al 2023)
A31: Great Ordovician Biodiversification Event | B31: GOBE | E31: persistent | F31: hothouse to warmhouse (background cooling) | G31: 490 | H31: 20000000 | I31: 50000000 | J31: 30000000 | K31: event duration ~30 Myr (~490 to ~460 Ma); arguably started earlier, ~500 Ma, and finished later, ~450 Ma (Katian, Late Ordovician)
A32: Steptoean Positive Carbon Isotope Excursion (SPICE) / End-Marjuman Biomere Extinction (EMBE; Paibian, Cambrian) | B32: SPICE | E32: transient | F32: Warmhouse or hothouse | G32: 495 | H32: 1600000 | I32: 3500000 | J32: 2600000 | K32: radiometrically constrained to 2.6 +0.9/-0.8 Myr duration (Farrell et al 2025)
A33: Redlichiid-Olenellid trilobite Extinction Carbon isotope Excursion (ROECE; Cambrian Stage 4–Miaolingian boundary) | B33: ROECE | E33: transient | F33: Hothouse | G33: 507 | H33: 10000 | I33: 1000000 | J33: 500000 | K33: very poorly constrained; likely a short event <1 Myr at or near the Cambrian Series 2-Miaolingian boundary (Jamart et al 2025)
A34: Sinsk Event / Archaeocyath Extinction Carbon isotope Excursion (AECE; Cambrian Stage 4) | B34: AECE | E34: transient | F34: Hothouse | G34: 513 | H34: 10000 | I34: 2600000 | J34: 1000000 | K34: poorly constrained; maximum age range between 514.45 ± 0.36 Ma to 511.87 ± 0.14 Ma (Myrow et al 2024) but likely on the order of 1 Myr or less (Zhuravlev et al 2023)
A35: Cambrian Agronomic Revolution | B35: bioturbation | E35: persistent | F35: Warmhouse to hothouse | G35: 545 | H35: 1000000 | I35: 40000000 | J35: 40000000 | K35: began in the late Ediacaran ~545 Ma and persisted through Cambrian Series 2 (i.e. 545 to 506 Ma; e.g. Mangano et al 2024)
A36: Eukaryogenesis | B36: eukaryotes | E36: persistent | F36: uncertain | G36: 2220 | H36: 10000000 | I36: 1000000000 | J36: 100000000 | K36: inception ~2.22 Ga (Mills et al 2022); duration estimated at tens to hundreds of millions of years with effects spanning billion year timescales
A37: Great Oxygenation Event | B37: GOE | E37: persistent | F37: uncertain | G37: 2400 | H37: 200000000 | I37: 1500000000 | J37: 500000000 | K37: event duration ~200 Myr (Gumsley et al 2017) with effects lasting through eukaryote evolution on billion year timescales

Sheet table_s4_summaries
A1: disruptor_type | B1: metric | C1: event_duration_min_yr | D1: event_duration_max_yr | E1: event_duration_est_yr
A2: persistent | B2: arithmetic mean | C2: =AVERAGEIF(table_s3_events!$E:$E, $A$2, table_s3_events!$H:$H) -> 51833333 | D2: =AVERAGEIF(table_s3_events!$E:$E, $A$2, table_s3_events!$I:$I) -> 4.6333333e+08 | E2: =AVERAGEIF(table_s3_events!$E:$E, $A$2, table_s3_events!$J:$J) -> 1.3416667e+08
A3: persistent | B3: median | C3: {=MEDIAN(IF(table_s3_events!$E:$E = $A$3, table_s3_events!$H:$H))} -> 25000000 | D3: {=MEDIAN(IF(table_s3_events!$E:$E = $A$3, table_s3_events!$I:$I))} -> 95000000 | E3: {=MEDIAN(IF(table_s3_events!$E:$E = $A$3, table_s3_events!$J:$J))} -> 67500000
A4: persistent | B4: standard deviation | C4: {=_xlfn.STDEV.P(IF(table_s3_events!$E:$E=$A$4, table_s3_events!$H:$H))} -> 68045124 | D4: {=_xlfn.STDEV.P(IF(table_s3_events!$E:$E=$A$4, table_s3_events!$I:$I))} -> 5.7505555e+08 | E4: {=_xlfn.STDEV.P(IF(table_s3_events!$E:$E=$A$4, table_s3_events!$J:$J))} -> 1.6518718e+08
A5: persistent | B5: maximum | C5: {=MAX(IF(table_s3_events!$E:$E=$A$5,table_s3_events!$H:$H))} -> 200000000 | D5: {=MAX(IF(table_s3_events!$E:$E=$A$4, table_s3_events!$I:$I))} -> 1500000000 | E5: {=MAX(IF(table_s3_events!$E:$E=$A$4, table_s3_events!$J:$J))} -> 500000000
A6: persistent | B6: minimum | C6: {=MIN(IF(table_s3_events!$E:$E=$A$4, table_s3_events!$H:$H))} -> 1000000 | D6: {=MIN(IF(table_s3_events!$E:$E=$A$4, table_s3_events!$I:$I))} -> 40000000 | E6: {=MIN(IF(table_s3_events!$E:$E=$A$4, table_s3_events!$J:$J))} -> 30000000
A7: persistent | B7: count | C7: {=COUNT(IF(table_s3_events!$E:$E=$A$7, table_s3_events!$H:$H))} -> 6 | D7: {=COUNT(IF(table_s3_events!$E:$E=$A$7, table_s3_events!$I:$I))} -> 6 | E7: {=COUNT(IF(table_s3_events!$E:$E=$A$7, table_s3_events!$J:$J))} -> 6
A8: transient | B8: arithmetic mean | C8: =AVERAGEIF(table_s3_events!$E:$E, $A$8, table_s3_events!$H:$H) -> 206600 | D8: =AVERAGEIF(table_s3_events!$E:$E, $A$8, table_s3_events!$I:$I) -> 1715640 | E8: =AVERAGEIF(table_s3_events!$E:$E, $A$8, table_s3_events!$J:$J) -> 795401.2
A9: transient | B9: median | C9: {=MEDIAN(IF(table_s3_events!$E:$E = $A$9, table_s3_events!$J:$J))} -> 500000 | D9: {=MEDIAN(IF(table_s3_events!$E:$E = $A$9, table_s3_events!$J:$J))} -> 500000 | E9: {=MEDIAN(IF(table_s3_events!$E:$E = $A$9, table_s3_events!$J:$J))} -> 500000
A10: transient | B10: standard deviation | C10: {=_xlfn.STDEV.P(IF(table_s3_events!$E:$E=$A$10, table_s3_events!$H:$H))} -> 373838.79 | D10: {=_xlfn.STDEV.P(IF(table_s3_events!$E:$E=$A$10, table_s3_events!$I:$I))} -> 1579114.5 | E10: {=_xlfn.STDEV.P(IF(table_s3_events!$E:$E=$A$10, table_s3_events!$J:$J))} -> 882153.01
A11: transient | B11: maximum | C11: {=MAX(IF(table_s3_events!$E:$E=$A$11, table_s3_events!$H:$H))} -> 1600000 | D11: {=MAX(IF(table_s3_events!$E:$E=$A$11, table_s3_events!$I:$I))} -> 7000000 | E11: {=MAX(IF(table_s3_events!$E:$E=$A$11, table_s3_events!$J:$J))} -> 4000000
A12: transient | B12: minimum | C12: {=MIN(IF(table_s3_events!$E:$E=$A$12, table_s3_events!$H:$H))} -> 1e-07 | D12: {=MIN(IF(table_s3_events!$E:$E=$A$12, table_s3_events!$I:$I))} -> 185000 | E12: {=MIN(IF(table_s3_events!$E:$E=$A$12, table_s3_events!$J:$J))} -> 30
A13: transient | B13: count | C13: {=COUNT(IF(table_s3_events!$E:$E=$A$13, table_s3_events!$H:$H))} -> 25 | D13: {=COUNT(IF(table_s3_events!$E:$E=$A$13, table_s3_events!$I:$I))} -> 25 | E13: {=COUNT(IF(table_s3_events!$E:$E=$A$13, table_s3_events!$J:$J))} -> 25

Sheet table_s5_biosphere_changes
A1: interval_name | B1: interval_abbreviation | C1: type | D1: age_estimate_ma | E1: reference | F1: change_type | G1: change_group | H1: change_metric | I1: change_value | J1: =_xlfn.XLOOKUP(A1, table_s3_events!A:A, table_s3_events!J:J) -> event_duration_est_yr | K1: change_per_msy_mgy | L1: percentage_change_rate_Myr | M1: notes | O1: change_group | P1: change_type | Q1: change_type_definition
A2: =_xlfn.XLOOKUP($B2, table_s3_events!$B:$B, table_s3_events!$A:$A) -> 3100 persistent - sustainable stewardship | B2: sustainable stewardship: 3100 | C2: =_xlfn.XLOOKUP($B2, table_s3_events!$B:$B, table_s3_events!$E:$E) -> sustainable stewardship | D2: =_xlfn.XLOOKUP($B2, table_s3_events!$B:$B, table_s3_events!$G:$G) -> -0.0011 | E2: estimate | F2: genus | G2: global | H2: percent | I2: 2 | J2: =_xlfn.XLOOKUP(A2, table_s3_events!A:A, table_s3_events!J:J) -> 3300 | K2: =IF(OR(F2="species", F2="genus"), (I2*10^4)/J2,"NA") -> 6.0606061 | L2: =IF(H2="percent", I2/(J2/10^6), "NA") -> 606.06061 | M2: assume halting and reversing biosphere degredation by 2100 in an integrated action portfolio (IAP) scenario (Leclere et al 2020) and supporting new symbioses at a rate of at least 10 speciation events per million species years (Thomas 2015) | O2: unspecified | P2: species | Q2: change in species; typically richness
A3: =_xlfn.XLOOKUP($B3, table_s3_events!$B:$B, table_s3_events!$A:$A) -> 3100 persistent - sustainable stewardship | B3: sustainable stewardship: 3100 | C3: =_xlfn.XLOOKUP($B3, table_s3_events!$B:$B, table_s3_events!$E:$E) -> sustainable stewardship | D3: =_xlfn.XLOOKUP($B3, table_s3_events!$B:$B, table_s3_events!$G:$G) -> -0.0011 | E3: estimate | F3: species | G3: global | H3: percent | I3: 5 | J3: =_xlfn.XLOOKUP(A3, table_s3_events!A:A, table_s3_events!J:J) -> 3300 | K3: =IF(OR(F3="species", F3="genus"), (I3*10^4)/J3,"NA") -> 15.151515 | L3: =IF(H3="percent", I3/(J3/10^6), "NA") -> 1515.1515 | M3: assume halting and reversing biosphere degredation by 2100 in an integrated action portfolio (IAP) scenario (Leclere et al 2020) and supporting new symbioses at a rate of at least 10 speciation events per million species years (Thomas 2015) | O3: global | P3: genus | Q3: change in genus; typically richness
A4: =_xlfn.XLOOKUP($B4, table_s3_events!$B:$B, table_s3_events!$A:$A) -> 3100 transient - business as usual | B4: business as usual: 3100 | C4: =_xlfn.XLOOKUP($B4, table_s3_events!$B:$B, table_s3_events!$E:$E) -> business as usual | D4: =_xlfn.XLOOKUP($B4, table_s3_events!$B:$B, table_s3_events!$G:$G) -> -0.0011 | E4: Barnosky & Hadly 2026 | F4: species | G4: global | H4: percent | I4: -28 | J4: =_xlfn.XLOOKUP(A4, table_s3_events!A:A, table_s3_events!J:J) -> 3300 | K4: =IF(OR(F4="species", F4="genus"), (I4*10^4)/J4,"NA") -> -84.848485 | L4: =IF(H4="percent", I4/(J4/10^6), "NA") -> -8484.8485 | M4: assuming all 28 % of species at risk of extinction (IUCN) go extinct in the next 1000 years | O4: global macroscopic | P4: species | Q4: change in species; typically richness
A5: =_xlfn.XLOOKUP($B5, table_s3_events!$B:$B, table_s3_events!$A:$A) -> 3100 transient - business as usual | B5: business as usual: 3100 | C5: =_xlfn.XLOOKUP($B5, table_s3_events!$B:$B, table_s3_events!$E:$E) -> business as usual | D5: =_xlfn.XLOOKUP($B5, table_s3_events!$B:$B, table_s3_events!$G:$G) -> -0.0011 | E5: estimate | F5: species | G5: global | H5: percent | I5: -10 | J5: =_xlfn.XLOOKUP(A5, table_s3_events!A:A, table_s3_events!J:J) -> 3300 | K5: =IF(OR(F5="species", F5="genus"), (I5*10^4)/J5,"NA") -> -30.30303 | L5: =IF(H5="percent", I5/(J5/10^6), "NA") -> -3030.303 | M5: a lower estimate of 10% species extinction by 3100 | O5: global marine | P5: genus | Q5: change in genus; typically richness
A6: =_xlfn.XLOOKUP($B6, table_s3_events!$B:$B, table_s3_events!$A:$A) -> 3100 transient - business as usual | B6: business as usual: 3100 | C6: =_xlfn.XLOOKUP($B6, table_s3_events!$B:$B, table_s3_events!$E:$E) -> business as usual | D6: =_xlfn.XLOOKUP($B6, table_s3_events!$B:$B, table_s3_events!$G:$G) -> -0.0011 | E6: estimate | F6: genus | G6: global | H6: percent | I6: -5 | J6: =_xlfn.XLOOKUP(A6, table_s3_events!A:A, table_s3_events!J:J) -> 3300 | K6: =IF(OR(F6="species", F6="genus"), (I6*10^4)/J6,"NA") -> -15.151515 | L6: =IF(H6="percent", I6/(J6/10^6), "NA") -> -1515.1515 | M6: a lower estimate of 5% genus extinction by 3100 | O6: global terrestrial | P6: biomass | Q6: change in biomass; typically expressed as % pre-existing biomass
A7: =_xlfn.XLOOKUP($B7, table_s3_events!$B:$B, table_s3_events!$A:$A) -> 2100 persistent - sustainable stewardship | B7: sustainable stewardship: 2100 | C7: =_xlfn.XLOOKUP($B7, table_s3_events!$B:$B, table_s3_events!$E:$E) -> sustainable stewardship | D7: =_xlfn.XLOOKUP($B7, table_s3_events!$B:$B, table_s3_events!$G:$G) -> -0.0001 | E7: Leclere et al 2020 | F7: species | G7: global | H7: percent | I7: 0 | J7: =_xlfn.XLOOKUP(A7, table_s3_events!A:A, table_s3_events!J:J) -> 300 | K7: =IF(OR(F7="species", F7="genus"), (I7*10^4)/J7,"NA") -> 0 | L7: =IF(H7="percent", I7/(J7/10^6), "NA") -> 0 | M7: assume halting and reversing biosphere degredation by 2100 in an integrated action portfolio (IAP) scenario | O7: marine invertebrates | P7: productivity | Q7: change in NPP; typically expresses as % pre-existing NPP
A8: =_xlfn.XLOOKUP($B8, table_s3_events!$B:$B, table_s3_events!$A:$A) -> 2100 persistent - sustainable stewardship | B8: sustainable stewardship: 2100 | C8: =_xlfn.XLOOKUP($B8, table_s3_events!$B:$B, table_s3_events!$E:$E) -> sustainable stewardship | D8: =_xlfn.XLOOKUP($B8, table_s3_events!$B:$B, table_s3_events!$G:$G) -> -0.0001 | E8: Leclere et al 2020 | F8: genus | G8: global | H8: percent | I8: 0 | J8: =_xlfn.XLOOKUP(A8, table_s3_events!A:A, table_s3_events!J:J) -> 300 | K8: =IF(OR(F8="species", F8="genus"), (I8*10^4)/J8,"NA") -> 0 | L8: =IF(H8="percent", I8/(J8/10^6), "NA") -> 0 | M8: assume halting and reversing biosphere degredation by 2100 in an integrated action portfolio (IAP) scenario | O8: terrestrial vertebrates
A9: =_xlfn.XLOOKUP($B9, table_s3_events!$B:$B, table_s3_events!$A:$A) -> 2100 transient - business as usual | B9: business as usual: 2100 | C9: =_xlfn.XLOOKUP($B9, table_s3_events!$B:$B, table_s3_events!$E:$E) -> business as usual | D9: =_xlfn.XLOOKUP($B9, table_s3_events!$B:$B, table_s3_events!$G:$G) -> -0.0001 | E9: Wiens & Zelinka 2024 | F9: species | G9: global macroscopic | H9: percent | I9: -32 | J9: =_xlfn.XLOOKUP(A9, table_s3_events!A:A, table_s3_events!J:J) -> 300 | K9: =IF(OR(F9="species", F9="genus"), (I9*10^4)/J9,"NA") -> -1066.6667 | L9: =IF(H9="percent", I9/(J9/10^6), "NA") -> -106666.67 | O9: vertebrates
A10: =_xlfn.XLOOKUP($B10, table_s3_events!$B:$B, table_s3_events!$A:$A) -> 2100 transient - business as usual | B10: business as usual: 2100 | C10: =_xlfn.XLOOKUP($B10, table_s3_events!$B:$B, table_s3_events!$E:$E) -> business as usual | D10: =_xlfn.XLOOKUP($B10, table_s3_events!$B:$B, table_s3_events!$G:$G) -> -0.0001 | E10: Strona & Bradshaw 2022 | F10: species | G10: terrestrial vertebrates | H10: percent | I10: -27 | J10: =_xlfn.XLOOKUP(A10, table_s3_events!A:A, table_s3_events!J:J) -> 300 | K10: =IF(OR(F10="species", F10="genus"), (I10*10^4)/J10,"NA") -> -900 | L10: =IF(H10="percent", I10/(J10/10^6), "NA") -> -90000 | M10: SSP5-8.5 scenario | O10: benthic foraminifera
A11: =_xlfn.XLOOKUP($B11, table_s3_events!$B:$B, table_s3_events!$A:$A) -> 2100 transient - business as usual | B11: business as usual: 2100 | C11: =_xlfn.XLOOKUP($B11, table_s3_events!$B:$B, table_s3_events!$E:$E) -> business as usual | D11: =_xlfn.XLOOKUP($B11, table_s3_events!$B:$B, table_s3_events!$G:$G) -> -0.0001 | E11: Strona & Bradshaw 2022 | F11: species | G11: terrestrial vertebrates | H11: percent | I11: -17.6 | J11: =_xlfn.XLOOKUP(A11, table_s3_events!A:A, table_s3_events!J:J) -> 300 | K11: =IF(OR(F11="species", F11="genus"), (I11*10^4)/J11,"NA") -> -586.66667 | L11: =IF(H11="percent", I11/(J11/10^6), "NA") -> -58666.667 | M11: SSP4-6.0 scenario | O11: planktic foraminifera
A12: =_xlfn.XLOOKUP($B12, table_s3_events!$B:$B, table_s3_events!$A:$A) -> 2100 transient - business as usual | B12: business as usual: 2100 | C12: =_xlfn.XLOOKUP($B12, table_s3_events!$B:$B, table_s3_events!$E:$E) -> business as usual | D12: =_xlfn.XLOOKUP($B12, table_s3_events!$B:$B, table_s3_events!$G:$G) -> -0.0001 | E12: Wiens & Zelinka 2024 | F12: species | G12: global macroscopic | H12: percent | I12: -14 | J12: =_xlfn.XLOOKUP(A12, table_s3_events!A:A, table_s3_events!J:J) -> 300 | K12: =IF(OR(F12="species", F12="genus"), (I12*10^4)/J12,"NA") -> -466.66667 | L12: =IF(H12="percent", I12/(J12/10^6), "NA") -> -46666.667 | O12: mammals
A13: =_xlfn.XLOOKUP($B13, table_s3_events!$B:$B, table_s3_events!$A:$A) -> 2100 transient - business as usual | B13: business as usual: 2100 | C13: =_xlfn.XLOOKUP($B13, table_s3_events!$B:$B, table_s3_events!$E:$E) -> business as usual | D13: =_xlfn.XLOOKUP($B13, table_s3_events!$B:$B, table_s3_events!$G:$G) -> -0.0001 | E13: Strona & Bradshaw 2022 | F13: species | G13: terrestrial vertebrates | H13: percent | I13: -13 | J13: =_xlfn.XLOOKUP(A13, table_s3_events!A:A, table_s3_events!J:J) -> 300 | K13: =IF(OR(F13="species", F13="genus"), (I13*10^4)/J13,"NA") -> -433.33333 | L13: =IF(H13="percent", I13/(J13/10^6), "NA") -> -43333.333 | M13: SSP2-4.5 scenario | O13: osteichthyans
A14: =_xlfn.XLOOKUP($B14, table_s3_events!$B:$B, table_s3_events!$A:$A) -> 2100 transient - business as usual | B14: business as usual: 2100 | C14: =_xlfn.XLOOKUP($B14, table_s3_events!$B:$B, table_s3_events!$E:$E) -> business as usual | D14: =_xlfn.XLOOKUP($B14, table_s3_events!$B:$B, table_s3_events!$G:$G) -> -0.0001 | E14: Ceballos & Ehrlich 2023 | F14: genus | G14: vertebrates | H14: percent | I14: -7.8 | J14: =_xlfn.XLOOKUP(A14, table_s3_events!A:A, table_s3_events!J:J) -> 300 | K14: =IF(OR(F14="species", F14="genus"), (I14*10^4)/J14,"NA") -> -260 | L14: =IF(H14="percent", I14/(J14/10^6), "NA") -> -26000 | M14: following projections of vertebrate genera extinctions assuming the extinction of endangered monospecific genera (Ceballos & Ehrlich 2023 table 3) | O14: terrestrial primary productivity
A15: =_xlfn.XLOOKUP($B15, table_s3_events!$B:$B, table_s3_events!$A:$A) -> 2100 transient - business as usual | B15: business as usual: 2100 | C15: =_xlfn.XLOOKUP($B15, table_s3_events!$B:$B, table_s3_events!$E:$E) -> business as usual | D15: =_xlfn.XLOOKUP($B15, table_s3_events!$B:$B, table_s3_events!$G:$G) -> -0.0001 | E15: Leclere et al 2020 | F15: species | G15: global | H15: percent | I15: -3.8 | J15: =_xlfn.XLOOKUP(A15, table_s3_events!A:A, table_s3_events!J:J) -> 300 | K15: =IF(OR(F15="species", F15="genus"), (I15*10^4)/J15,"NA") -> -126.66667 | L15: =IF(H15="percent", I15/(J15/10^6), "NA") -> -12666.667 | M15: following the baseline (BASE = SSP2) scenario of Leclere et al 2020 (see their fig. 1 and extended data table 1) for 2100 using their peak loss rate for 2010 to 2100; alternative would be to take their linear rate of change for 2010 to 2050 of -0.68 %/decade and apply it to the 90 year interval making a loss rate of 6.12 % over 90 years | O15: global plants
A16: =_xlfn.XLOOKUP($B16, table_s3_events!$B:$B, table_s3_events!$A:$A) -> Recent past | B16: humans so far | C16: =_xlfn.XLOOKUP($B16, table_s3_events!$B:$B, table_s3_events!$E:$E) -> humans so far | D16: =_xlfn.XLOOKUP($B16, table_s3_events!$B:$B, table_s3_events!$G:$G) -> 0 | E16: Bar-On et al 2018 | F16: biomass | G16: mammals | H16: percent | I16: -83 | J16: =_xlfn.XLOOKUP(A16, table_s3_events!A:A, table_s3_events!J:J) -> 200 | K16: =IF(OR(F16="species", F16="genus"), (I16*10^4)/J16,"NA") -> NA | L16: =IF(H16="percent", I16/(J16/10^6), "NA") -> -415000 | M16: largely following data in Barnosky 2008 | O16: global animals
A17: =_xlfn.XLOOKUP($B17, table_s3_events!$B:$B, table_s3_events!$A:$A) -> Recent past | B17: humans so far | C17: =_xlfn.XLOOKUP($B17, table_s3_events!$B:$B, table_s3_events!$E:$E) -> humans so far | D17: =_xlfn.XLOOKUP($B17, table_s3_events!$B:$B, table_s3_events!$G:$G) -> 0 | E17: Bar-On et al 2018 | F17: species | G17: megafauna | H17: percent | I17: -50 | J17: =_xlfn.XLOOKUP(A17, table_s3_events!A:A, table_s3_events!J:J) -> 200 | K17: =IF(OR(F17="species", F17="genus"), (I17*10^4)/J17,"NA") -> -2500 | L17: =IF(H17="percent", I17/(J17/10^6), "NA") -> -250000 | O17: birds
A18: =_xlfn.XLOOKUP($B18, table_s3_events!$B:$B, table_s3_events!$A:$A) -> Recent past | B18: humans so far | C18: =_xlfn.XLOOKUP($B18, table_s3_events!$B:$B, table_s3_events!$E:$E) -> humans so far | D18: =_xlfn.XLOOKUP($B18, table_s3_events!$B:$B, table_s3_events!$G:$G) -> 0 | E18: PBScience 2025 | F18: productivity | G18: terrestrial primary productivity | H18: percent | I18: -30 | J18: =_xlfn.XLOOKUP(A18, table_s3_events!A:A, table_s3_events!J:J) -> 200 | K18: =IF(OR(F18="species", F18="genus"), (I18*10^4)/J18,"NA") -> NA | L18: =IF(H18="percent", I18/(J18/10^6), "NA") -> -150000 | M18: HANPP from PBScience 2025 | O18: habitable shelf space
A19: =_xlfn.XLOOKUP($B19, table_s3_events!$B:$B, table_s3_events!$A:$A) -> Recent past | B19: humans so far | C19: =_xlfn.XLOOKUP($B19, table_s3_events!$B:$B, table_s3_events!$E:$E) -> humans so far | D19: =_xlfn.XLOOKUP($B19, table_s3_events!$B:$B, table_s3_events!$G:$G) -> 0 | E19: Hatton et al 2021 | F19: biomass | G19: large fish and marine mammals | H19: percent | I19: -60 | J19: =_xlfn.XLOOKUP(A19, table_s3_events!A:A, table_s3_events!J:J) -> 200 | K19: =IF(OR(F19="species", F19="genus"), (I19*10^4)/J19,"NA") -> NA | L19: =IF(H19="percent", I19/(J19/10^6), "NA") -> -300000 | M19: estimate of lost biomass of marine mammals and fish weighing more than 10 g over 20th century due to fishing and whaling (~2 Gt loss) | O19: large fish and marine mammals
A20: =_xlfn.XLOOKUP($B20, table_s3_events!$B:$B, table_s3_events!$A:$A) -> Recent past | B20: humans so far | C20: =_xlfn.XLOOKUP($B20, table_s3_events!$B:$B, table_s3_events!$E:$E) -> humans so far | D20: =_xlfn.XLOOKUP($B20, table_s3_events!$B:$B, table_s3_events!$G:$G) -> 0 | E20: Wiens & Saban 2025 | F20: genus | G20: mammals | H20: percent | I20: -1.61 | J20: =_xlfn.XLOOKUP(A20, table_s3_events!A:A, table_s3_events!J:J) -> 200 | K20: =IF(OR(F20="species", F20="genus"), (I20*10^4)/J20,"NA") -> -80.5 | L20: =IF(H20="percent", I20/(J20/10^6), "NA") -> -8050 | M20: values from extinct genera as proportion of IUCN assessed genera | O20: megafauna
A21: =_xlfn.XLOOKUP($B21, table_s3_events!$B:$B, table_s3_events!$A:$A) -> Recent past | B21: humans so far | C21: =_xlfn.XLOOKUP($B21, table_s3_events!$B:$B, table_s3_events!$E:$E) -> humans so far | D21: =_xlfn.XLOOKUP($B21, table_s3_events!$B:$B, table_s3_events!$G:$G) -> 0 | E21: Wiens & Saban 2025 | F21: genus | G21: birds | H21: percent | I21: -1.54 | J21: =_xlfn.XLOOKUP(A21, table_s3_events!A:A, table_s3_events!J:J) -> 200 | K21: =IF(OR(F21="species", F21="genus"), (I21*10^4)/J21,"NA") -> -77 | L21: =IF(H21="percent", I21/(J21/10^6), "NA") -> -7700 | M21: values from extinct genera as proportion of IUCN assessed genera | O21: marine megafauna
